File: Validation/Benchmark dataset validation/E3076-DS1(2018).txt
<Preamble>
E3076-DS1(2018)
Contact information:  ASTM International
www.astm.org/E08.03.05
Copyright ASTM International 2018
Status:
This is a benchmark data set to evaluate computer implementation of
the algorithm in standard E3076.
E3076 includes a step-by-step analysis of this data set with results
for each step.
The format of this data set conforms with E2443-05(2010).
There is no Specimen_Info required to analyze this data set.
The expected results are:
Data Quality Metrics
Digital Resolution
	Relative x-resolution	0.67	(≤ 1) PASS
	% at this resolution	15.6
	% in zeroth bin	6.4
	Relative y-resolution	0.33	(≤1) PASS
	% at this resolution	4.6
	% in zeroth bin	90.8
Noise
	Relative x-noise	0.325	(≤1) PASS
	Relative y-noise	0.144	(≤1) PASS
Fit Quality Metrics
Curvature
	1st Quartile relative residual slope	0.366	(-1≤ and ≤1) PASS
	Number of points	25	(>5)
	4th Quartile relative residual slope	0.205	(-1≤ and ≤1) PASS
	Number of points	25	(>5)
Fit Range
	Relative Fit Range	0.926	(≤1) PASS
Slope Determination Results
Final Slope	328.10 kN/mm
True Intercept	-0.03761 kN
Lower y bound of fit range	5.457 kN
Upper y bound of fit range	14.36 kN
</Preamble>

<Specimen_Info>

</Specimen_Info>

<Data>
extensometer	force
mm	kN
5.79192000E-05	0.19137880
1.45421000E-04	0.20929070
8.82377000E-04	0.43320330
2.35295800E-03	0.82217990
3.84881800E-03	1.18193500
5.27089500E-03	1.48835900
6.02313500E-03	1.78308500
6.83975500E-03	2.07144400
7.75495000E-03	2.35575300
8.57098000E-03	2.64048900
9.31607000E-03	2.92133400
1.02226400E-02	3.20380200
1.11670300E-02	3.48500800
1.20271550E-02	3.76643900
1.26806300E-02	4.04829700
1.35925850E-02	4.33008900
1.44984750E-02	4.61227700
1.51950550E-02	4.89384100
1.60569450E-02	5.17596900
1.68223200E-02	5.45663200
1.76550100E-02	5.73913600
1.84276300E-02	6.02196800
1.93286150E-02	6.30340700
2.01693400E-02	6.58631900
2.11058950E-02	6.86713400
2.19259450E-02	7.15003900
2.27175750E-02	7.43239600
2.34831450E-02	7.71463500
2.44947550E-02	7.99583600
2.53548800E-02	8.27999400
2.61375950E-02	8.56210800
2.69639150E-02	8.84234400
2.79967900E-02	9.12570900
2.88341800E-02	9.40928100
2.98524550E-02	9.69179300
3.05466900E-02	9.97380800
3.14767750E-02	10.25508000
3.22561600E-02	10.53643000
3.30458350E-02	10.81847000
3.39284950E-02	11.10082000
3.46765250E-02	11.38244000
3.55894600E-02	11.66553000
3.65332650E-02	11.94895000
3.73866300E-02	12.23063000
3.77639800E-02	12.34370000
3.87004350E-02	12.62379000
3.93662500E-02	12.90811000
4.02955550E-02	13.19374000
4.11919350E-02	13.48256000
4.18853850E-02	13.77567000
4.30252600E-02	14.06853000
4.39639750E-02	14.35957000
4.49114000E-02	14.65764000
4.58827400E-02	14.95349000
4.69311000E-02	15.24768000
4.78935200E-02	15.54583000
4.87091600E-02	15.84843000
4.97861300E-02	16.14497000
5.06300000E-02	16.44385000
5.17815000E-02	16.74671000
5.29503000E-02	17.04359000
5.38423500E-02	17.33789000
5.49552000E-02	17.63631000
5.61853500E-02	17.93144000
5.72084000E-02	18.22612000
5.83985500E-02	18.52388000
5.95485000E-02	18.81865000
6.10115500E-02	19.10760000
6.24256000E-02	19.39611000
6.36430000E-02	19.68243000
6.50406500E-02	19.96573000
6.67740500E-02	20.24855000
6.82719500E-02	20.52518000
6.99472500E-02	20.79324000
7.19052000E-02	21.06003000
7.36951000E-02	21.31740000
7.57695000E-02	21.56617000
7.79338000E-02	21.80954000
8.01497500E-02	22.04479000
8.27370000E-02	22.26628000
8.54790500E-02	22.47761000
8.83221500E-02	22.67972000
9.11243500E-02	22.86347000
9.46402000E-02	23.03167000
9.80983500E-02	23.18837000
1.00757800E-01	23.28816000
1.03425950E-01	23.38049000
1.07634350E-01	23.52319000
1.12861450E-01	23.66533000
1.18361850E-01	23.77720000
1.24406000E-01	23.86939000
1.30644800E-01	23.94779000
1.37197750E-01	24.01434000
1.43816950E-01	24.07711000
1.50330700E-01	24.13010000
1.57017500E-01	24.18101000
1.63578650E-01	24.23269000
1.70371750E-01	24.27994000
1.76985450E-01	24.33086000
1.83717200E-01	24.37994000
1.90135300E-01	24.43025000
1.97029550E-01	24.48248000
2.03543900E-01	24.53575000
2.10424600E-01	24.58781000
2.17052800E-01	24.64186000
2.23439950E-01	24.69439000
2.29966100E-01	24.74795000
2.36543150E-01	24.80357000
2.43163400E-01	24.85965000
2.49406050E-01	24.91679000
2.56182000E-01	24.97316000
2.62456150E-01	25.03000000
2.68902400E-01	25.08958000
2.75329900E-01	25.14625000
2.81839650E-01	25.20253000
2.88031100E-01	25.26042000
2.94484000E-01	25.31637000
3.00757500E-01	25.37653000
3.07092600E-01	25.43333000
3.13538450E-01	25.49337000
3.19724050E-01	25.55086000
3.26084950E-01	25.60726000
3.32437000E-01	25.66788000
3.38842550E-01	25.72802000
3.45095250E-01	25.78253000
3.51263250E-01	25.84366000
3.57604700E-01	25.89817000
3.64030250E-01	25.95717000
3.70103050E-01	26.01534000
3.76391350E-01	26.07270000
3.82741100E-01	26.13075000
3.89108700E-01	26.19028000
3.95319200E-01	26.24465000
4.01449700E-01	26.30227000
4.07771600E-01	26.35762000
4.14063950E-01	26.41379000
4.20339300E-01	26.47035000
4.26710500E-01	26.52730000
4.32967000E-01	26.58246000
4.39072750E-01	26.63734000
4.45367100E-01	26.69108000
4.51743600E-01	26.74986000
4.58072550E-01	26.80303000
4.64404400E-01	26.85932000
4.70625650E-01	26.91474000
4.76970900E-01	26.96589000
4.83021950E-01	27.02081000
4.89522450E-01	27.07532000
4.95824800E-01	27.12763000
5.01959500E-01	27.18436000
5.08247000E-01	27.23409000
5.14562000E-01	27.28811000
5.20839000E-01	27.34365000
5.26988500E-01	27.39528000
5.33345000E-01	27.44802000
5.39731000E-01	27.49975000
5.46209500E-01	27.55150000
5.52255000E-01	27.60161000
5.58234000E-01	27.65385000
5.64739500E-01	27.70716000
5.71013500E-01	27.76035000
5.77457000E-01	27.80923000
5.83571000E-01	27.86048000
5.90023500E-01	27.91018000
5.96178000E-01	27.96025000
6.02485000E-01	28.01219000
6.08837500E-01	28.05988000
6.15166000E-01	28.10957000
6.21422000E-01	28.16164000
6.24140500E-01	28.18164000
6.31087500E-01	28.30588000
6.46165500E-01	28.61190000
6.68013000E-01	28.80186000
6.90469000E-01	28.97792000
7.12464000E-01	29.14198000
7.33853000E-01	29.30009000
7.54998000E-01	29.45533000
7.75812000E-01	29.60590000
7.96371000E-01	29.75332000
8.16586000E-01	29.90358000
8.36781500E-01	30.04907000
8.56994500E-01	30.19013000
8.77216500E-01	30.33088000
8.97391000E-01	30.47167000
9.17454500E-01	30.61174000
9.37831500E-01	30.75101000
9.58053000E-01	30.88937000
9.78212000E-01	31.02294000
9.98557500E-01	31.15891000
1.01868700E+00	31.29134000
1.03887650E+00	31.42314000
1.05908350E+00	31.55271000
1.07929950E+00	31.68414000
1.09945000E+00	31.81048000
1.11956000E+00	31.94031000
1.13976500E+00	32.06554000
1.16017150E+00	32.18980000
1.18013600E+00	32.31427000
1.20015000E+00	32.43793000
1.22041600E+00	32.56182000
1.24066200E+00	32.68435000
1.26068950E+00	32.80449000
1.28094600E+00	32.92316000
1.30139650E+00	33.04265000
1.32150150E+00	33.16201000
1.34190450E+00	33.27847000
1.36225800E+00	33.39490000
1.38238050E+00	33.51008000
1.40258150E+00	33.62499000
1.42279400E+00	33.73942000
1.44312850E+00	33.85223000
1.46342150E+00	33.96503000
1.48341300E+00	34.07212000
1.50363150E+00	34.18560000
1.52419900E+00	34.29305000
1.54391450E+00	34.40255000
1.56443800E+00	34.51336000
1.58489200E+00	34.62187000
1.60502350E+00	34.72813000
1.62535250E+00	34.83479000
1.64557950E+00	34.93860000
1.66590900E+00	35.04416000
1.68604450E+00	35.14821000
1.70647550E+00	35.25081000
1.72685050E+00	35.35455000
1.74688150E+00	35.45665000
1.76712700E+00	35.55869000
1.78759550E+00	35.65898000
1.80785600E+00	35.75905000
1.82802800E+00	35.86059000
1.84833450E+00	35.95923000
1.86848600E+00	36.05660000
1.88881000E+00	36.15648000
1.90921650E+00	36.25141000
1.92943600E+00	36.34726000
1.94956850E+00	36.44544000
1.96999450E+00	36.54062000
1.99014000E+00	36.63715000
2.01052250E+00	36.73218000
2.03094150E+00	36.82694000
2.05114200E+00	36.91871000
2.07140950E+00	37.01376000
2.09179400E+00	37.10428000
2.11196200E+00	37.19573000
2.13212700E+00	37.28797000
2.15252450E+00	37.37923000
2.17279000E+00	37.47088000
2.19344100E+00	37.56134000
2.21350850E+00	37.64941000
2.23401450E+00	37.73876000
2.25398750E+00	37.82791000
2.27437950E+00	37.91635000
2.29453850E+00	38.00258000
2.31492050E+00	38.09288000
2.33527650E+00	38.17969000
2.35563700E+00	38.26644000
2.37564350E+00	38.35185000
2.39612450E+00	38.43800000
2.41638000E+00	38.52352000
2.43670850E+00	38.60746000
2.45696750E+00	38.69457000
2.47735450E+00	38.77725000
2.49769750E+00	38.86163000
2.51813500E+00	38.94736000
2.53843600E+00	39.02902000
2.55869750E+00	39.11049000
2.57904450E+00	39.19452000
2.59933900E+00	39.27734000
2.61970550E+00	39.35907000
2.64004050E+00	39.44077000
2.66026750E+00	39.52078000
2.68044000E+00	39.60039000
2.70073100E+00	39.68044000
2.72109900E+00	39.76117000
2.74130250E+00	39.83990000
2.76160050E+00	39.91916000
2.78181250E+00	39.99962000
2.80217700E+00	40.07906000
2.82248700E+00	40.15808000
2.84296150E+00	40.23443000
2.86327050E+00	40.30954000
2.88321000E+00	40.38892000
2.90333600E+00	40.46676000
2.92370550E+00	40.54571000
2.94391800E+00	40.62183000
2.96413050E+00	40.69585000
2.98429100E+00	40.77153000
3.00451800E+00	40.84800000
3.02491650E+00	40.92267000
3.04505050E+00	40.99884000
3.06527900E+00	41.07196000
3.08531750E+00	41.14717000
3.10567400E+00	41.22057000
3.12580400E+00	41.29405000
3.14608150E+00	41.36824000
3.16627000E+00	41.44045000
3.18614900E+00	41.51379000
3.20652650E+00	41.58767000
3.22682100E+00	41.66094000
3.24682200E+00	41.73261000
3.26712750E+00	41.80502000
3.28720350E+00	41.87526000
3.30736550E+00	41.94630000
3.32754350E+00	42.01914000
3.34774600E+00	42.08893000
3.36804550E+00	42.15924000
3.38796250E+00	42.23240000
3.40816300E+00	42.30194000
3.42869150E+00	42.37140000
3.44855000E+00	42.44089000
3.46888350E+00	42.50951000
3.48885900E+00	42.57916000
3.50902550E+00	42.65103000
3.52912750E+00	42.71916000
3.54930050E+00	42.78626000
3.56955400E+00	42.85613000
3.58974250E+00	42.92422000
3.60988500E+00	42.99219000
3.63023650E+00	43.05903000
3.65037150E+00	43.12682000
3.67040700E+00	43.19416000
3.69070900E+00	43.26262000
3.71072000E+00	43.32972000
3.73115800E+00	43.39496000
3.75108650E+00	43.46249000
3.77150350E+00	43.52749000
3.79161700E+00	43.59253000
3.81138450E+00	43.65882000
3.83147400E+00	43.72588000
3.85186650E+00	43.79157000
3.87189150E+00	43.85560000
3.89199800E+00	43.92185000
3.91216050E+00	43.98505000
3.93240200E+00	44.04990000
3.95240650E+00	44.11404000
3.97258900E+00	44.17729000
3.99276600E+00	44.24358000
4.01293900E+00	44.30763000
4.03314050E+00	44.37037000
4.05347850E+00	44.43268000
4.07351400E+00	44.49588000
4.09366950E+00	44.55905000
4.11356300E+00	44.62244000
4.13378800E+00	44.68663000
4.15406400E+00	44.74852000
4.17399800E+00	44.80900000
4.19451950E+00	44.87251000
4.21474350E+00	44.93365000
4.23458500E+00	44.99632000
4.25484700E+00	45.05691000
4.27516300E+00	45.12153000
4.29551450E+00	45.18211000
4.31563800E+00	45.24282000
4.33577400E+00	45.30386000
4.35621200E+00	45.36361000
4.37615650E+00	45.42342000
4.39648500E+00	45.48570000
4.41651800E+00	45.54382000
4.43656100E+00	45.60404000
4.45678550E+00	45.66597000
4.47716500E+00	45.72486000
4.49734050E+00	45.78314000
4.51727750E+00	45.84254000
4.53743900E+00	45.90083000
4.55761500E+00	45.95876000
4.57765150E+00	46.02048000
4.59814500E+00	46.08079000
4.61840950E+00	46.13903000
4.63864450E+00	46.19554000
4.65882400E+00	46.25411000
4.67887200E+00	46.31261000
4.69910600E+00	46.37158000
4.71936800E+00	46.42864000
4.73942100E+00	46.48584000
4.75991950E+00	46.54528000
4.78025650E+00	46.60084000
4.80030050E+00	46.65707000
4.82064950E+00	46.71403000
4.84066250E+00	46.77006000
4.86098250E+00	46.82598000
4.88116050E+00	46.88464000
4.90148450E+00	46.94262000
4.92197350E+00	46.99746000
4.94202100E+00	47.05132000
4.96222000E+00	47.10871000
4.98243600E+00	47.16484000
5.00266000E+00	47.22045000
5.02293000E+00	47.27515000
5.04318500E+00	47.33090000
5.06341500E+00	47.38571000
5.08378000E+00	47.44327000
5.10377000E+00	47.49451000
5.12416500E+00	47.54932000
5.14418000E+00	47.60455000
5.16425000E+00	47.65718000
5.18458000E+00	47.71102000
5.20464000E+00	47.77048000
5.22518000E+00	47.82152000
5.24516000E+00	47.87347000
5.26543000E+00	47.92747000
5.28576500E+00	47.98080000
5.30586000E+00	48.03433000
5.32628500E+00	48.08838000
5.34648000E+00	48.14200000
5.36668500E+00	48.19423000
5.38696000E+00	48.24817000
5.40734000E+00	48.29869000
5.42773000E+00	48.35289000
5.44793000E+00	48.40447000
5.46816000E+00	48.45764000
5.48853500E+00	48.50658000
5.50875000E+00	48.56202000
5.52906500E+00	48.61273000
5.54949500E+00	48.66381000
5.56949500E+00	48.71603000
5.58996000E+00	48.76782000
5.61021500E+00	48.81766000
5.63051500E+00	48.86840000
5.65087000E+00	48.91952000
5.67092500E+00	48.97026000
5.69126000E+00	49.02174000
5.71170500E+00	49.07288000
5.73186000E+00	49.12080000
5.75223500E+00	49.17039000
5.77236000E+00	49.22223000
5.79250500E+00	49.27053000
5.81247500E+00	49.32387000
5.83323000E+00	49.37262000
5.85353500E+00	49.42220000
5.87362000E+00	49.46990000
5.89403000E+00	49.51963000
5.91469500E+00	49.56896000
5.93463000E+00	49.61743000
5.95506000E+00	49.66770000
5.97541500E+00	49.71733000
5.99577000E+00	49.76467000
6.01607500E+00	49.81279000
6.03668500E+00	49.86161000
6.05694000E+00	49.90942000
6.07700500E+00	49.95784000
6.09737000E+00	50.00580000
6.11776000E+00	50.05342000
6.13823000E+00	50.10177000
6.15861000E+00	50.14966000
6.17884500E+00	50.19622000
6.19927000E+00	50.24462000
6.21968500E+00	50.29199000
6.23977000E+00	50.33753000
6.26062500E+00	50.38657000
6.28088000E+00	50.43521000
6.30113500E+00	50.47941000
6.32186500E+00	50.52486000
6.34198500E+00	50.57143000
6.36243000E+00	50.61851000
6.38270000E+00	50.66460000
6.40311500E+00	50.71142000
6.42378500E+00	50.75691000
6.44383000E+00	50.80321000
6.46451500E+00	50.84898000
6.48484500E+00	50.89245000
6.50512000E+00	50.93712000
6.52547000E+00	50.98292000
6.54589000E+00	51.02805000
6.56632500E+00	51.07430000
6.58641000E+00	51.12154000
6.60694500E+00	51.16390000
6.62764500E+00	51.20726000
6.64760000E+00	51.25226000
6.66820500E+00	51.29852000
6.68879000E+00	51.34141000
6.70888500E+00	51.38596000
6.72952000E+00	51.43049000
6.75008500E+00	51.47282000
6.77061000E+00	51.51726000
6.79089000E+00	51.56122000
6.81101500E+00	51.60421000
6.83178500E+00	51.64893000
6.85212000E+00	51.69170000
6.87264000E+00	51.73383000
6.89319500E+00	51.77770000
6.91367000E+00	51.82155000
6.93420500E+00	51.86260000
6.95466000E+00	51.90389000
6.97511000E+00	51.94780000
6.99540500E+00	51.98961000
7.01586500E+00	52.03309000
7.03655000E+00	52.07579000
7.05687000E+00	52.11686000
7.07734500E+00	52.15672000
7.09789500E+00	52.19955000
7.11824500E+00	52.24178000
7.13869500E+00	52.28320000
7.15907500E+00	52.32506000
7.17972500E+00	52.36634000
7.20027500E+00	52.40811000
7.22059500E+00	52.44949000
7.24125500E+00	52.48955000
7.26167500E+00	52.52897000
7.28212500E+00	52.57192000
7.30272000E+00	52.61279000
7.32323000E+00	52.65126000
7.34386000E+00	52.69314000
7.36456500E+00	52.73328000
7.38489000E+00	52.77075000
7.40564000E+00	52.81240000
7.42572500E+00	52.85277000
7.44643000E+00	52.89183000
7.46694500E+00	52.93259000
7.48759000E+00	52.97245000
7.50809500E+00	53.00971000
7.52863000E+00	53.04996000
7.54939500E+00	53.08747000
7.56966500E+00	53.12629000
7.59029500E+00	53.16691000
7.61102000E+00	53.20606000
7.63128500E+00	53.24408000
7.65209500E+00	53.28288000
7.67276500E+00	53.32204000
7.69339000E+00	53.35953000
7.71391500E+00	53.39698000
7.73442500E+00	53.43532000
7.75504000E+00	53.47192000
7.77558000E+00	53.51053000
7.79619000E+00	53.55047000
7.81695000E+00	53.58557000
7.83737500E+00	53.62322000
7.85802000E+00	53.66095000
7.87866000E+00	53.69899000
7.89935000E+00	53.73524000
7.91991000E+00	53.77282000
7.94056500E+00	53.80905000
7.96148500E+00	53.84667000
7.98211500E+00	53.88433000
8.00278500E+00	53.91998000
8.02339500E+00	53.95438000
8.04398500E+00	53.99063000
8.06455500E+00	54.02851000
8.08500000E+00	54.06392000
8.10605000E+00	54.10092000
8.12690500E+00	54.13566000
8.14719000E+00	54.17135000
8.16825000E+00	54.20621000
8.18896500E+00	54.24318000
8.20955000E+00	54.27617000
8.23016500E+00	54.31126000
8.25119000E+00	54.34951000
8.27195000E+00	54.38483000
8.29250500E+00	54.41761000
8.31337000E+00	54.45310000
8.33430500E+00	54.48723000
8.35474500E+00	54.52151000
8.37579500E+00	54.55682000
8.39652000E+00	54.59097000
8.41733000E+00	54.62565000
8.43812500E+00	54.65984000
8.45911500E+00	54.69160000
8.47963000E+00	54.72730000
8.50026000E+00	54.76211000
8.52135000E+00	54.79509000
8.54237000E+00	54.82865000
8.56299500E+00	54.86292000
8.58426000E+00	54.89655000
8.60499000E+00	54.92802000
8.62575500E+00	54.96267000
8.64652000E+00	54.99338000
8.66732500E+00	55.02776000
8.68824000E+00	55.06182000
8.70906500E+00	55.09470000
8.73034500E+00	55.12609000
8.75118000E+00	55.15779000
8.77207500E+00	55.18937000
8.79306500E+00	55.22145000
8.81399500E+00	55.25332000
8.83489500E+00	55.28813000
8.85584000E+00	55.31824000
8.87672000E+00	55.35108000
8.89786500E+00	55.38076000
8.91853500E+00	55.41117000
8.93963500E+00	55.44308000
8.96054000E+00	55.47551000
8.98142000E+00	55.50818000
9.00262500E+00	55.53806000
9.02363000E+00	55.56984000
9.04468500E+00	55.60012000
9.06546000E+00	55.62972000
9.08661000E+00	55.66072000
9.10777000E+00	55.69080000
9.12846500E+00	55.72045000
9.14957000E+00	55.75103000
9.17070000E+00	55.78285000
9.19176000E+00	55.81262000
9.21279500E+00	55.84180000
9.23383000E+00	55.87217000
9.25499000E+00	55.89987000
9.27564000E+00	55.93098000
9.29697000E+00	55.96234000
9.31831000E+00	55.98932000
9.33916000E+00	56.01913000
9.36032000E+00	56.04858000
9.38151500E+00	56.07713000
9.40280500E+00	56.10568000
9.42380500E+00	56.13555000
9.44502000E+00	56.16338000
9.46622500E+00	56.19222000
9.48697000E+00	56.22157000
9.50845000E+00	56.25025000
9.52956500E+00	56.27785000
9.55076000E+00	56.30488000
9.57175000E+00	56.33203000
9.59290500E+00	56.36021000
9.61416000E+00	56.38923000
9.63534500E+00	56.41692000
9.65669000E+00	56.44454000
9.67815500E+00	56.47305000
9.69903500E+00	56.49829000
9.72061000E+00	56.52658000
9.74179500E+00	56.55450000
9.76334000E+00	56.58143000
9.78435500E+00	56.60619000
9.80580000E+00	56.63534000
9.82727500E+00	56.66201000
9.84840000E+00	56.68853000
9.86986000E+00	56.71334000
9.89124500E+00	56.73969000
9.91229500E+00	56.76510000
9.93397500E+00	56.79262000
9.95514000E+00	56.81892000
9.97670000E+00	56.84413000
9.99797500E+00	56.87086000
1.00194300E+01	56.89667000
1.00410400E+01	56.92101000
1.00621350E+01	56.94641000
1.00838700E+01	56.97277000
1.01049550E+01	56.99790000
1.01264900E+01	57.02434000
1.01481950E+01	57.04898000
1.01699500E+01	57.07303000
1.01912150E+01	57.09727000
1.02124150E+01	57.12212000
1.02345200E+01	57.14747000
1.02558100E+01	57.17186000
1.02774450E+01	57.19860000
1.02991400E+01	57.22052000
1.03204700E+01	57.24483000
1.03422300E+01	57.26965000
1.03636050E+01	57.29170000
1.03854150E+01	57.31421000
1.04067250E+01	57.34023000
1.04283300E+01	57.36285000
1.04500700E+01	57.38732000
1.04716750E+01	57.41310000
1.04935450E+01	57.43625000
1.05150500E+01	57.45643000
1.05368750E+01	57.48007000
1.05584750E+01	57.50311000
1.05800250E+01	57.52494000
1.06019350E+01	57.55085000
1.06235000E+01	57.57120000
1.06454150E+01	57.59320000
1.06673100E+01	57.61480000
1.06889250E+01	57.63819000
1.07105700E+01	57.65961000
1.07323400E+01	57.68239000
1.07540550E+01	57.70522000
1.07758650E+01	57.72769000
1.07979550E+01	57.74909000
1.08196550E+01	57.76945000
1.08413600E+01	57.79038000
1.08634500E+01	57.80972000
1.08849500E+01	57.83229000
1.09067850E+01	57.85413000
1.09284850E+01	57.87666000
1.09507100E+01	57.89761000
1.09725600E+01	57.91807000
1.09946150E+01	57.93733000
1.10165750E+01	57.95869000
1.10382300E+01	57.97741000
1.10603100E+01	57.99989000
1.10824700E+01	58.02102000
1.11043050E+01	58.04080000
1.11265200E+01	58.06091000
1.11483600E+01	58.08136000
1.11705950E+01	58.09977000
1.11921250E+01	58.12006000
1.12145250E+01	58.14012000
1.12365650E+01	58.16034000
1.12585850E+01	58.17748000
1.12809150E+01	58.19843000
1.13028700E+01	58.21760000
1.13251200E+01	58.23628000
1.13467900E+01	58.25475000
1.13694050E+01	58.27420000
1.13911700E+01	58.29269000
1.14134350E+01	58.31397000
1.14358050E+01	58.33242000
1.14579150E+01	58.34925000
1.14803550E+01	58.36746000
1.15024100E+01	58.38496000
1.15248700E+01	58.40393000
1.15469000E+01	58.42137000
1.15693050E+01	58.43969000
1.15915650E+01	58.45546000
1.16138700E+01	58.47637000
1.16362400E+01	58.49267000
1.16585450E+01	58.51001000
1.16809400E+01	58.52640000
1.17030550E+01	58.54428000
1.17254250E+01	58.56119000
1.17477250E+01	58.57861000
1.17700050E+01	58.59812000
1.17927800E+01	58.61399000
1.18149650E+01	58.63026000
1.18374350E+01	58.64787000
1.18601700E+01	58.66237000
1.18829050E+01	58.68001000
1.19050400E+01	58.69734000
1.19275750E+01	58.71266000
1.19503900E+01	58.72918000
1.19725900E+01	58.74496000
1.19953450E+01	58.76061000
1.20177450E+01	58.77444000
1.20404650E+01	58.79048000
1.20628450E+01	58.80619000
1.20856800E+01	58.82273000
1.21080750E+01	58.83753000
1.21307000E+01	58.85543000
1.21539050E+01	58.86768000
1.21762850E+01	58.88442000
1.21990800E+01	58.89869000
1.22216600E+01	58.91208000
1.22446900E+01	58.92761000
1.22671500E+01	58.94331000
1.22901750E+01	58.95907000
1.23130600E+01	58.97276000
1.23357950E+01	58.98615000
1.23587250E+01	58.99990000
1.23813550E+01	59.01257000
1.24041850E+01	59.02851000
1.24269850E+01	59.04301000
1.24503200E+01	59.05767000
1.24731500E+01	59.07106000
1.24962750E+01	59.08291000
1.25194800E+01	59.09514000
1.25419750E+01	59.11093000
1.25654150E+01	59.12374000
1.25879450E+01	59.13440000
1.26111050E+01	59.15074000
1.26341950E+01	59.16326000
1.26574000E+01	59.17472000
1.26801750E+01	59.18736000
1.27036800E+01	59.20028000
1.27266750E+01	59.21115000
1.27495900E+01	59.22483000
1.27728650E+01	59.23954000
1.27959050E+01	59.25011000
1.28190800E+01	59.26378000
1.28421850E+01	59.27565000
1.28658700E+01	59.28528000
1.28887300E+01	59.29797000
1.29121250E+01	59.31079000
1.29356550E+01	59.32065000
1.29588050E+01	59.33337000
1.29822350E+01	59.34618000
1.30056950E+01	59.35541000
1.30290400E+01	59.36595000
1.30523600E+01	59.37775000
1.30761800E+01	59.38724000
1.30992600E+01	59.39898000
1.31227700E+01	59.40960000
1.31464150E+01	59.42159000
1.31699750E+01	59.43223000
1.31932850E+01	59.44195000
1.32168300E+01	59.45072000
1.32403850E+01	59.46018000
1.32639400E+01	59.47357000
1.32876450E+01	59.48274000
1.33109900E+01	59.49503000
1.33349400E+01	59.50452000
1.33589250E+01	59.51306000
1.33824350E+01	59.51943000
1.34056350E+01	59.53063000
1.34296550E+01	59.54191000
1.34532900E+01	59.55086000
1.34772100E+01	59.55949000
1.35009300E+01	59.56909000
1.35245450E+01	59.57774000
1.35486900E+01	59.58709000
1.35727400E+01	59.59553000
1.35967050E+01	59.60340000
1.36202700E+01	59.61257000
1.36444250E+01	59.62122000
1.36682300E+01	59.62901000
1.36924550E+01	59.64034000
1.37162500E+01	59.64711000
1.37404900E+01	59.65310000
1.37642800E+01	59.66268000
1.37886250E+01	59.67095000
1.38125050E+01	59.67750000
1.38368450E+01	59.68618000
1.38611100E+01	59.69413000
1.38852450E+01	59.70085000
1.39096250E+01	59.70793000
1.39338600E+01	59.71685000
1.39583000E+01	59.72394000
1.39826050E+01	59.72868000
1.40068650E+01	59.73793000
1.40308150E+01	59.74259000
1.40555300E+01	59.75185000
1.40797050E+01	59.75948000
1.41043200E+01	59.76444000
1.41287950E+01	59.77017000
1.41536550E+01	59.77815000
1.41778800E+01	59.78383000
1.42025450E+01	59.78966000
1.42269850E+01	59.79632000
1.42515600E+01	59.80386000
1.42763400E+01	59.80816000
1.43008750E+01	59.81288000
1.43255750E+01	59.81950000
1.43503550E+01	59.82392000
1.43750050E+01	59.83189000
1.43997300E+01	59.83639000
1.44247750E+01	59.84334000
1.44493500E+01	59.84722000
1.44743750E+01	59.85134000
1.44992250E+01	59.85495000
1.45239500E+01	59.86062000
1.45490200E+01	59.86663000
1.45742150E+01	59.87002000
1.45986050E+01	59.87574000
1.46241100E+01	59.88165000
1.46487950E+01	59.88472000
1.46740750E+01	59.88740000
1.46989600E+01	59.89172000
1.47242900E+01	59.89538000
1.47492000E+01	59.89929000
1.47746850E+01	59.90575000
1.47997800E+01	59.90922000
1.48251100E+01	59.91184000
1.48503850E+01	59.91553000
1.48756950E+01	59.91789000
1.49007250E+01	59.92290000
1.49265650E+01	59.92706000
1.49516600E+01	59.92907000
1.49774350E+01	59.93126000
1.50029050E+01	59.93570000
1.50282250E+01	59.93595000
1.50537500E+01	59.93795000
1.50793450E+01	59.94341000
1.51049150E+01	59.94600000
1.51307600E+01	59.94686000
1.51562000E+01	59.94943000
1.51822200E+01	59.95308000
1.52078650E+01	59.95342000
1.52334400E+01	59.95513000
1.52592800E+01	59.95672000
1.52851850E+01	59.95824000
1.53107050E+01	59.96135000
1.53368300E+01	59.96290000
1.53627150E+01	59.96373000
1.53887100E+01	59.96603000
1.54149350E+01	59.96673000
1.54407600E+01	59.96662000
1.54667500E+01	59.96658000
1.54930650E+01	59.96979000
1.55188700E+01	59.97105000
1.55453800E+01	59.96844000
1.55713200E+01	59.97152000
1.55977400E+01	59.97270000
1.56239250E+01	59.97089000
1.56502200E+01	59.97102000
1.56764450E+01	59.97177000
1.57029250E+01	59.97066000
1.57288850E+01	59.97143000
1.57557150E+01	59.97251000
1.57820800E+01	59.97109000
1.58088600E+01	59.97011000
1.58354050E+01	59.96892000
1.58618700E+01	59.96717000
1.58881750E+01	59.96835000
1.59154300E+01	59.96818000
1.59416950E+01	59.96464000
1.59686800E+01	59.96353000
1.59954200E+01	59.96484000
1.60226350E+01	59.95904000
1.60492150E+01	59.95793000
1.60760950E+01	59.95712000
1.61028650E+01	59.95453000
1.61299600E+01	59.95152000
1.61567800E+01	59.95093000
1.61841400E+01	59.94845000
1.62113300E+01	59.94521000
1.62383950E+01	59.94357000
1.62656350E+01	59.93862000
1.62927200E+01	59.93597000
1.63199200E+01	59.93435000
1.63470750E+01	59.93071000
1.63746900E+01	59.92653000
1.64020100E+01	59.92320000
1.64296850E+01	59.91793000
1.64568250E+01	59.91396000
1.64844500E+01	59.91147000
1.65117050E+01	59.90649000
1.65393950E+01	59.90086000
1.65668500E+01	59.89653000
1.65945150E+01	59.89227000
1.66222700E+01	59.88647000
1.66499350E+01	59.88126000
1.66777250E+01	59.87364000
1.67053800E+01	59.86785000
1.67331500E+01	59.86338000
1.67611400E+01	59.85668000
1.67891000E+01	59.84851000
1.68168400E+01	59.84381000
1.68453800E+01	59.83586000
1.68730850E+01	59.82630000
1.69010800E+01	59.81945000
1.69287300E+01	59.81213000
1.69569400E+01	59.80313000
1.69853100E+01	59.79543000
1.70133000E+01	59.78662000
1.70419650E+01	59.77852000
1.70699600E+01	59.76500000
1.70982800E+01	59.75602000
1.71265500E+01	59.74646000
1.71550000E+01	59.73562000
1.71834250E+01	59.72461000
1.72120950E+01	59.71149000
1.72402750E+01	59.69830000
1.72690550E+01	59.68601000
1.72975800E+01	59.67233000
1.73261000E+01	59.65808000
1.73546100E+01	59.64577000
1.73832250E+01	59.62983000
1.74122900E+01	59.61344000
1.74408050E+01	59.59690000
1.74697450E+01	59.57872000
1.74982950E+01	59.55776000
1.75269850E+01	59.54093000
1.75559750E+01	59.52204000
1.75846450E+01	59.50143000
1.76142050E+01	59.47790000
1.76430350E+01	59.45480000
1.76722050E+01	59.42859000
1.77011500E+01	59.40295000
1.77301800E+01	59.37732000
1.77593950E+01	59.34688000
1.77881400E+01	59.31876000
1.78178750E+01	59.28881000
1.78468200E+01	59.25314000
1.78763850E+01	59.21715000
1.79055300E+01	59.18210000
1.79349800E+01	59.14148000
1.79641750E+01	59.10237000
1.79934200E+01	59.06025000
1.80234100E+01	59.01504000
1.80525550E+01	58.96786000
1.80823600E+01	58.91967000
1.81120450E+01	58.86658000
1.81414150E+01	58.81247000
1.81713750E+01	58.75723000
1.82008500E+01	58.69986000
1.82306400E+01	58.63837000
1.82603600E+01	58.57559000
1.82904550E+01	58.50738000
1.83201600E+01	58.43704000
1.83499150E+01	58.36667000
1.83798650E+01	58.29275000
1.84099200E+01	58.21604000
1.84401450E+01	58.13562000
1.84702700E+01	58.05191000
1.85005050E+01	57.96663000
1.85304550E+01	57.87910000
1.85605300E+01	57.78914000
1.85911600E+01	57.69502000
1.86211550E+01	57.59655000
1.86517500E+01	57.49842000
1.86822150E+01	57.39649000
1.87124750E+01	57.29039000
1.87432000E+01	57.18334000
1.87735100E+01	57.06983000
1.88040400E+01	56.95694000
1.88346850E+01	56.84149000
1.88654450E+01	56.72204000
1.88960350E+01	56.59822000
1.89266750E+01	56.47462000
1.89579750E+01	56.34406000
1.89884650E+01	56.21372000
1.90194300E+01	56.08038000
1.90504700E+01	55.94131000
1.90813400E+01	55.80196000
1.91125750E+01	55.66174000
1.91434500E+01	55.51499000
1.91747550E+01	55.36706000
1.92058400E+01	55.21590000
1.92371550E+01	55.05941000
1.92684850E+01	54.90174000
1.92996550E+01	54.74572000
1.93311050E+01	54.58059000
1.93623300E+01	54.41449000
1.93939050E+01	54.24760000
1.94252700E+01	54.07591000
1.94569000E+01	53.90006000
1.94884150E+01	53.72393000
1.95203000E+01	53.54365000
1.95519350E+01	53.36072000
1.95838600E+01	53.17435000
1.96157450E+01	52.98518000
1.96474150E+01	52.79199000
1.96797550E+01	52.59658000
1.97116000E+01	52.39767000
1.97437150E+01	52.19488000
1.97758400E+01	51.99267000
1.98078100E+01	51.78416000
1.98401050E+01	51.57553000
1.98724250E+01	51.36199000
1.99047500E+01	51.14636000
1.99375100E+01	50.92364000
1.99696200E+01	50.70130000
2.00019650E+01	50.47624000
2.00344950E+01	50.24694000
2.00665100E+01	50.01523000
2.00996400E+01	49.78128000
2.01321500E+01	49.54160000
2.01653300E+01	49.29710000
2.01981500E+01	49.05091000
2.02308200E+01	48.79992000
2.02636950E+01	48.54670000
2.02968750E+01	48.28956000
2.03297250E+01	48.02884000
2.03634350E+01	47.76145000
2.03967800E+01	47.49131000
2.04302100E+01	47.21490000
2.04638350E+01	46.93600000
2.04972100E+01	46.65295000
2.05309550E+01	46.36455000
2.05647950E+01	46.06860000
2.05987450E+01	45.76913000
2.06325700E+01	45.46225000
2.06670800E+01	45.14331000
2.07014200E+01	44.81665000
2.07363000E+01	44.46943000
1.69980550E+01	24.85073000
</Data>